Workbook

Sheet How To Use
A8: Fix & Flip Financial Model — JV Partner Template
A9: How to use this workbook
A11: WHO THIS IS FOR
A12: Deals with two (or more) capital/operating parties who split profit via a priority-ordered waterfall — e.g. a capital partner (JV Party A) and an operating/sweat-equity partner (JV Party B). If your client is a single borrower with no partner split, use the companion Borrower Version template instead — it has the same deal-economics tabs without the waterfall complexity.
A14: WHAT MAKES THE WATERFALL TAB DIFFERENT
A15: Most fix-and-flip models just show 'party gets X%.' This one properly caps every distribution step at cash actually remaining, in strict priority order — so if the sale price disappoints, the model shows who actually absorbs the shortfall (usually the most junior party) instead of quietly showing a negative number or letting the senior party's payout float free of reality. This is the single most common modeling mistake in JV waterfalls and the main reason this template is worth reusing.
A17: STEP 1 — Assumptions tab
A18: Replace every [BRACKETED] placeholder and blue example figure with the client's actual deal terms: property details, loan terms, rehab budget total, holding costs, timeline, and — critically — the actual JV agreement's economic terms (preferred return rate, residual split, capital exposure definition). Read the client's actual JV agreement or operating agreement before filling these in — do not assume the example rates apply.
A20: STEP 2 — Rehab Budget tab
A21: Replace the example category rows with the client's real itemized contractor budget. Keep one row per line item; the category subtotals and grand total update automatically.
A23: STEP 3 — Waterfall priority order
A24: The Disposition & Returns tab's step order (liens → senior party capital return + preferred return → contingency/additional-capital mechanisms → junior party fee → residual split) reflects a common JV structure, but every deal's actual agreement may order these differently. Re-read the client's agreement's distribution-of-proceeds section and re-order the steps in this tab to match — the capping logic (MIN formulas holding each step at cash actually remaining) works the same regardless of order, but the order itself must match the real contract or the output is meaningless.
... A33: Cells and notes marked in red/yellow throughout are meant for you, the preparer — flagging assumptions, unresolved 'need to verify' items, or internal reasoning. Review every flagged note before sending to a client and either resolve it or convert it into client-appropriate language. Don't ship a model with 'confirm with Harold'-style internal notes intact.

Sheet Summary
A8: Fix & Flip Financial Analysis
A9: [Property Address] | [Capital Partner Entity] / [Operating Partner Entity] (JV)
A11: Prepared: | B11: =TODAY() -> 46236
A13: KEY DEAL METRICS
A15: Purchase Price | B15: =Assumptions!B12 -> 300000
A16: After Repair Value (ARV) | B16: =Assumptions!B14 -> 450000
A17: Total Rehab Budget | B17: ='Rehab Budget'!C30 -> 45000
A18: Total Project Cost (Purchase + Closing + Rehab) | B18: ='Sources & Uses'!B10 -> 353000
A19: Total Cash Required (all-in) | B19: ='Sources & Uses'!B31 -> 117250
A21: PROJECT PROFIT & RETURN
A23: Net Sale Proceeds (after commission & closing costs) | B23: ='Disposition & Returns'!B10 -> 416250
A24: Less: Loan Payoff (senior lien) | B24: =-'Disposition & Returns'!B15 -> -250000
A25: Less: Total Capital Invested (both parties, out-of-pocket) | B25: =-('Disposition & Returns'!B104+'Disposition & Returns'!B106) -> -98000
A26: NET PROJECT PROFIT | B26: ='Disposition & Returns'!B109 -> 68250
A27: Return on Capital Invested (Total ROI) | B27: =B26/-B25 -> 0.69642857
A28: Annualized ROI (based on hold period) | B28: =B27*(12/Assumptions!B34) -> 1.6714286
A30: WATERFALL SPLIT (Title % is for reporting only — the waterfall below governs actual payout)
A32: Party A — Senior Capital Return + Preferred Return | B32: ='Disposition & Returns'!B37 -> 150200
A33: Party B — Contingency Fallback Funding (if applicable) | B33: ='Disposition & Returns'!B47+'Disposition & Returns'!B96 -> 0
A34: Party A — Additional Capital Contributions + Return | B34: ='Disposition & Returns'!B60 -> 0
A35: Party B — Reimbursements + Management/Operating Fee | B35: ='Disposition & Returns'!B71+'Disposition & Returns'!B81 -> 13920
A36: Residual Split | B36: ='Disposition & Returns'!B88 -> 2130
A38: Party A — Total Distribution | B38: ='Disposition & Returns'!B97 -> 150626
A39: Party B — Total Distribution | B39: ='Disposition & Returns'!B98 -> 15624
A41: Party A — Net Profit | B41: ='Disposition & Returns'!B105 -> 52626
A42: Party B — Net Profit | B42: ='Disposition & Returns'!B107 -> 15624
A44: TEMPLATE NOTES — REMOVE BEFORE SENDING TO CLIENT
A46: • This is a TEMPLATE. Every dollar figure, rate, and JV clause reference must be replaced with the actual deal's terms before use.
A47: • The waterfall step order on the Disposition & Returns tab must match the client's actual JV/operating agreement's distribution-of-proceeds section — verify before relying on it.
A48: • Delete the contingency and additional-capital mechanisms entirely if the client's deal doesn't have them.
A49: • Test the model at a below-ARV sale price before delivering — confirm no distribution goes negative (see How To Use tab, Step 5).

Sheet Assumptions
A1: Assumptions & Inputs
A2: Blue = replace with actual deal figures | Yellow = confirm/customize per client's JV agreement
A4: PROPERTY
A6: Address | B6: [Property Address]
A7: Property Type | B7: [e.g. Single Family Residence]
A8: Requested Closing Date | B8: [Closing Date]
A10: ACQUISITION
A12: Purchase Price | B12: 300000 | C12: EXAMPLE — replace with actual purchase price.
A13: As-Is Value | B13: 300000 | C13: EXAMPLE.
A14: After Repair Value (ARV) | B14: 450000 | C14: EXAMPLE.
A15: Earnest Money Deposit (already paid) | B15: 1000 | C15: EXAMPLE.
A16: Seller / Broker Credits | B16: 0 | C16: EXAMPLE.
A18: LOAN TERMS
A20: Loan Amount | B20: 250000 | C20: EXAMPLE — pull from actual lender term sheet.
A21: Interest Rate (annual, simple, interest-only) | B21: 0.12 | C21: EXAMPLE.
A22: Total Estimated Closing Costs | B22: 8000 | C22: EXAMPLE.
A23: Monthly Interest-Only Payment | B23: =B20*B21/12 -> 2500
A24: Lender-Required Payment Reserve (if applicable) | B24: 0 | C24: EXAMPLE — confirm actual reserve requirement, if any.
A26: REHAB BUDGET
A28: Total Rehab Budget (itemized — see Rehab Budget tab) | B28: ='Rehab Budget'!C30 -> 45000
A30: TIMELINE — CONFIRM WITH CLIENT
A32: Rehab Period (months) | B32: 3 | C32: EXAMPLE — set based on actual scope of work.
A33: Marketing & Closing Period (months) | B33: 2 | C33: EXAMPLE.
A34: Total Hold Period (months) | B34: =B32+B33 -> 5
A36: HOLDING COSTS — CONFIRM WITH CLIENT
A38: Property Tax (monthly) | B38: 200 | C38: EXAMPLE — pull from county tax records.
A39: Insurance (monthly) | B39: 200 | C39: EXAMPLE — get an actual quote.
A40: Utilities (monthly) | B40: 150 | C40: EXAMPLE.
A41: HOA Dues (monthly) | B41: 0 | C41: EXAMPLE — $0 if not applicable.
A43: DISPOSITION — CONFIRM WITH CLIENT
A45: Target Sale Price | B45: =B14 -> 450000 | C45: Set equal to ARV by default. Overwrite with a specific target/list price to test scenarios.
A46: Selling Commission (% of sale price) | B46: 0.06 | C46: EXAMPLE — confirm local market rate.
A47: Selling Closing Costs (% of sale price) | B47: 0.015 | C47: EXAMPLE.
A49: JV WATERFALL INPUTS — MUST MATCH CLIENT'S ACTUAL JV/OPERATING AGREEMENT
A51: Party A (Capital Partner) — Title Interest % | B51: 0.51 | C51: Title/reporting only — confirm whether title % drives economics or a separate waterfall governs, per the actual agreement.
A52: Party B (Operating Partner) — Title Interest % | B52: 0.49
A54: Total Capital Exposure (Party A's full acquisition + rehab + closing cost basis) | B54: 348000 | C54: EXAMPLE — this is the base the preferred return is calculated on. Definition varies by agreement — read the actual JV/operating agreement's capital-exposure clause before setting this.
A55: Primary Lien Amount to be Repaid (loan payoff) | B55: =B20 -> 250000 | C55: Defaults to the loan amount above — confirm against the actual payoff statement at closing.
A56: Secondary Lien Amount to be Repaid (if any) | B56: 0
A57: Preferred Return Rate (flat, applied to Total Capital Exposure) | B57: 0.15 | C57: EXAMPLE — this MUST match the actual agreement's preferred-return clause. Confirm whether it's flat or annualized/prorated by hold period.
...

Sheet Rehab Budget
A1: Rehab Budget — Itemized
A2: REPLACE with client's actual itemized contractor budget
A4: Category | B4: Line Item | C4: Budgeted Cost | D4: Scope Notes
A5: Exterior | B5: Roofing | C5: 6000 | D5: EXAMPLE ROW — replace or delete
A6: Exterior | B6: Siding / Paint | C6: 5000 | D6: EXAMPLE ROW
A7: Exterior | B7: Windows / Doors | C7: 3000 | D7: EXAMPLE ROW
A8: Exterior | B8: Landscaping | C8: 1500 | D8: EXAMPLE ROW
A9: Interior/Structural | B9: Framing / Structural Repair | C9: 2000 | D9: EXAMPLE ROW
A10: Interior/Structural | B10: Drywall / Paint | C10: 3500 | D10: EXAMPLE ROW
A11: Interior/Structural | B11: Flooring | C11: 4000 | D11: EXAMPLE ROW
A12: Kitchen | B12: Cabinets / Countertops | C12: 6000 | D12: EXAMPLE ROW
A13: Kitchen | B13: Appliances | C13: 2500 | D13: EXAMPLE ROW
A14: Bathroom | B14: Fixtures / Tile | C14: 2000 | D14: EXAMPLE ROW
A15: Systems (Elec/HVAC/Plumbing) | B15: Electrical | C15: 1500 | D15: EXAMPLE ROW
A16: Systems (Elec/HVAC/Plumbing) | B16: HVAC | C16: 2000 | D16: EXAMPLE ROW
... A20: Admin/Contingency | B20: Dumpster / Trash Out / Cleanup | C20: 500 | D20: EXAMPLE ROW
A22: SUBTOTAL BY CATEGORY
A23: Exterior | C23: =SUMIF($A$5:$A$20,A23,$C$5:$C$20) -> 15500
A24: Interior/Structural | C24: =SUMIF($A$5:$A$20,A24,$C$5:$C$20) -> 9500
A25: Kitchen | C25: =SUMIF($A$5:$A$20,A25,$C$5:$C$20) -> 8500
A26: Bathroom | C26: =SUMIF($A$5:$A$20,A26,$C$5:$C$20) -> 2000
A27: Systems (Elec/HVAC/Plumbing) | C27: =SUMIF($A$5:$A$20,A27,$C$5:$C$20) -> 4500
A28: Admin/Contingency | C28: =SUMIF($A$5:$A$20,A28,$C$5:$C$20) -> 5000
A30: TOTAL REHAB BUDGET | C30: =SUM(C5:C20) -> 45000

Sheet Sources & Uses
A1: Sources & Uses of Funds
A2: Closing through end of projected hold period
A4: USES OF FUNDS
A6: Purchase Price | B6: =Assumptions!B12 -> 300000
A7: Loan Closing Costs | B7: =Assumptions!B22 -> 8000
A8: Rehab Budget | B8: ='Rehab Budget'!C30 -> 45000
A10: Total Project Cost (at closing) | B10: =B6+B7+B8 -> 353000
A12: Lender-Required Payment Reserve | B12: =Assumptions!B24 -> 0
A13: Additional Loan Interest Beyond Reserve (if hold exceeds reserve period) | B13: =MAX(0,(Assumptions!B23*Assumptions!B34)-Assumptions!B24) -> 12500
A14: Property Tax — full hold period | B14: =Assumptions!B38*Assumptions!B34 -> 1000
A15: Insurance — full hold period | B15: =Assumptions!B39*Assumptions!B34 -> 1000
A16: Utilities — full hold period | B16: =Assumptions!B40*Assumptions!B34 -> 750
A17: HOA Dues — full hold period | B17: =Assumptions!B41*Assumptions!B34 -> 0
A19: Total Holding-Period Cash Requirement | B19: =B12+B13+B14+B15+B16+B17 -> 15250
A21: TOTAL USES OF FUNDS | B21: =B10+B19 -> 368250
A23: SOURCES OF FUNDS
A25: Loan | B25: =Assumptions!B20 -> 250000
A26: Seller / Broker Credits | B26: =Assumptions!B16 -> 0
A27: Earnest Money Deposit (already applied) | B27: =Assumptions!B15 -> 1000
A29: Total Lender/Credit-Side Financing | B29: =B25+B26+B27 -> 251000
A31: Total Capital Required (cash to close + reserve + holding overage) | B31: ='Sources & Uses'!B21-B29 -> 117250
A33: TOTAL SOURCES OF FUNDS | B33: =B29+B31 -> 368250

Sheet Monthly Cash Flow
A1: Monthly Cash Flow — Closing Through Sale
A2: Projected month-by-month cash flow over the hold period
A4: Line Item | B4: Month 0 (Closing) | C4: Month 1 | D4: Month 2 | E4: Month 3 | F4: Month 4 | G4: Month 5 | H4: Month 6 | I4: Total
A5: Purchase Price | B5: =Assumptions!B12 -> 300000 | C5: 0 | D5: 0 | E5: 0 | F5: 0 | G5: 0 | H5: 0 | I5: =SUM(B5:H5) -> 300000
A6: Loan Closing Costs | B6: =Assumptions!B22 -> 8000 | C6: 0 | D6: 0 | E6: 0 | F6: 0 | G6: 0 | H6: 0 | I6: =SUM(B6:H6) -> 8000
A7: Rehab Outlay (paid upfront, each month) | B7: =0 -> 0 | C7: ='Rehab Budget'!C30/Assumptions!B32 -> 15000 | D7: ='Rehab Budget'!C30/Assumptions!B32 -> 15000 | E7: ='Rehab Budget'!C30/Assumptions!B32 -> 15000 | F7: 0 | G7: 0 | H7: 0 | I7: =SUM(B7:H7) -> 45000
A8: Rehab Draw Reimbursement (if lender draws — adjust timing to match actual loan) | B8: =0 -> 0 | C8: 0 | D8: =-'Rehab Budget'!C30/Assumptions!B32 -> -15000 | E8: =-'Rehab Budget'!C30/Assumptions!B32 -> -15000 | F8: =-'Rehab Budget'!C30/Assumptions!B32 -> -15000 | G8: 0 | H8: 0 | I8: =SUM(B8:H8) -> -45000
A9: Loan Interest-Only Payment | B9: =0 -> 0 | C9: =Assumptions!B23 -> 2500 | D9: =Assumptions!B23 -> 2500 | E9: =Assumptions!B23 -> 2500 | F9: =Assumptions!B23 -> 2500 | G9: =Assumptions!B23 -> 2500 | H9: =Assumptions!B23 -> 2500 | I9: =SUM(B9:H9) -> 15000
A10: Property Tax | B10: =0 -> 0 | C10: =Assumptions!B38 -> 200 | D10: =Assumptions!B38 -> 200 | E10: =Assumptions!B38 -> 200 | F10: =Assumptions!B38 -> 200 | G10: =Assumptions!B38 -> 200 | H10: =Assumptions!B38 -> 200 | I10: =SUM(B10:H10) -> 1200
A11: Insurance | B11: =0 -> 0 | C11: =Assumptions!B39 -> 200 | D11: =Assumptions!B39 -> 200 | E11: =Assumptions!B39 -> 200 | F11: =Assumptions!B39 -> 200 | G11: =Assumptions!B39 -> 200 | H11: =Assumptions!B39 -> 200 | I11: =SUM(B11:H11) -> 1200
A12: Utilities | B12: =0 -> 0 | C12: =Assumptions!B40 -> 150 | D12: =Assumptions!B40 -> 150 | E12: =Assumptions!B40 -> 150 | F12: =Assumptions!B40 -> 150 | G12: =Assumptions!B40 -> 150 | H12: =Assumptions!B40 -> 150 | I12: =SUM(B12:H12) -> 900
A13: HOA | B13: =0 -> 0 | C13: =Assumptions!B41 -> 0 | D13: =Assumptions!B41 -> 0 | E13: =Assumptions!B41 -> 0 | F13: =Assumptions!B41 -> 0 | G13: =Assumptions!B41 -> 0 | H13: =Assumptions!B41 -> 0 | I13: =SUM(B13:H13) -> 0
A14: Less: Seller/Broker Credits & EMD Applied | B14: =-(Assumptions!B16+Assumptions!B15) -> -1000 | C14: 0 | D14: 0 | E14: 0 | F14: 0 | G14: 0 | H14: 0 | I14: =SUM(B14:H14) -> -1000
A16: MONTHLY CASH OUTFLOW | B16: =SUM(B5:B14) -> 307000 | C16: =SUM(C5:C14) -> 18050 | D16: =SUM(D5:D14) -> 3050 | E16: =SUM(E5:E14) -> 3050 | F16: =SUM(F5:F14) -> -11950 | G16: =SUM(G5:G14) -> 3050 | H16: =SUM(H5:H14) -> 3050 | I16: =SUM(I5:I14) -> 325300
A17: CUMULATIVE CASH INVESTED | B17: =B16 -> 307000 | C17: =B17+C16 -> 325050 | D17: =C17+D16 -> 328100 | E17: =D17+E16 -> 331150 | F17: =E17+F16 -> 319200 | G17: =F17+G16 -> 322250 | H17: =G17+H16 -> 325300
A20: Rehab outlay/reimbursement timing shown here is an EXAMPLE (upfront, reimbursed the following month). Adjust to match the client's actual lender draw schedule and inspection timing.

Sheet Disposition & Returns
A1: Disposition & Returns
A2: Sale proceeds and the JV profit waterfall — capped priority order. Re-order steps to match the client's actual agreement.
A4: SALE PROCEEDS (Step A — costs of sale)
A6: Target Sale Price | B6: =Assumptions!B45 -> 450000
A7: Less: Selling Commission | B7: =-Assumptions!B45*Assumptions!B46 -> -27000
A8: Less: Selling Closing Costs | B8: =-Assumptions!B45*Assumptions!B47 -> -6750
A10: Net Sale Proceeds (available for the waterfall below) | B10: =B6+B7+B8 -> 416250
A12: PROFIT WATERFALL — each step capped by cash actually remaining (no negative payouts)
A14: Step B — Primary Lien Holder — Nominal Amount Owed | B14: =Assumptions!B55 -> 250000
A15: Step B — Primary Lien Holder — Actual Paid (capped at cash remaining) | B15: =MIN(B10,MAX(0,B14)) -> 250000
A16: Step B — Primary Lien Holder — Shortfall (unpaid if underfunded) | B16: =B14-B15 -> 0
A18: Cash Remaining After Step B — Primary Lien Holder | B18: =B10-B15 -> 166250
A20: Step C — Secondary Lien Holder — Nominal Amount Owed | B20: =Assumptions!B56 -> 0
A21: Step C — Secondary Lien Holder — Actual Paid (capped at cash remaining) | B21: =MIN(B18,MAX(0,B20)) -> 0
A22: Step C — Secondary Lien Holder — Shortfall (unpaid if underfunded) | B22: =B20-B21 -> 0
A24: Cash Remaining After Step C — Secondary Lien Holder | B24: =B18-B21 -> 166250
A26: Step D — Party A: Return of Capital + Preferred Return
A28: Total Capital Exposure | B28: =Assumptions!B54 -> 348000
A29: Less: Primary Lien Actually Repaid at Step B (credited as partial return of capital) | B29: =-B15 -> -250000
A30: Party A Full Equity Requirement (Capital Exposure − Primary Lien Repaid) | B30: =B28-B15 -> 98000
A31: Party A Actual Available Capital (editable — see Assumptions) | B31: =Assumptions!B67 -> 98000
A32: Shortfall Covered by Party B Contingency (see below — delete section if not applicable) | B32: =MAX(0,B30-B31) -> 0
A33: Party A Equity Returned (= actual capital contributed) | B33: =B31 -> 98000
A34: Preferred Return (rate x Total Capital Exposure — confirm flat vs. annualized per agreement) | B34: =B28*Assumptions!B57 -> 52200
A36: Step D Total to Party A — Nominal Amount Owed | B36: =B33+B34 -> 150200
A37: Step D Total to Party A — Actual Paid (capped at cash remaining) | B37: =MIN(B24,MAX(0,B36)) -> 150200
A38: Step D Total to Party A — Shortfall (unpaid if underfunded) | B38: =B36-B37 -> 0
A40: Cash Remaining After Step D Total to Party A | B40: =B24-B37 -> 16050
A42: CONTINGENCY PRINCIPAL — Party B Fallback Funding (DELETE if not applicable to this deal)
A44: Party B Contingency Contribution (= shortfall above) | B44: =B32 -> 0
A46: Return of Contingency Capital (principal) — Nominal Amount Owed | B46: =B44 -> 0
A47: Return of Contingency Capital (principal) — Actual Paid (capped at cash remaining) | B47: =MIN(B40,MAX(0,B46)) -> 0
A48: Return of Contingency Capital (principal) — Shortfall (unpaid if underfunded) | B48: =B46-B47 -> 0
A50: Cash Remaining After Return of Contingency Capital (principal) | B50: =B40-B47 -> 16050
A52: Premium on Contingency Contribution (nominal — charged to Party A's share below, not this pool) | B52: =B44*Assumptions!B57 -> 0
A54: Step E — Party A: Additional Capital Contributions + Return (DELETE if not applicable)
A56: Additional Contributions | B56: =Assumptions!B58 -> 0
A57: Return on Additional Contributions | B57: =B56*Assumptions!B57 -> 0
A59: Step E Total to Party A — Nominal Amount Owed | B59: =B56+B57 -> 0
A60: Step E Total to Party A — Actual Paid (capped at cash remaining) | B60: =MIN(B50,MAX(0,B59)) -> 0
...
