Workbook

Sheet How To Use
A1: Fix & Flip Financial Model — Quick Screen Template
A2: Pre-diligence deal screener — before a term sheet, before an itemized rehab budget
A4: WHO THIS IS FOR
A6: A fast go/no-go read on a property BEFORE you've requested a lender term sheet or a contractor's itemized bid — the filter that decides whether a deal is worth the time to fully underwrite. Two audiences:
A7: • You, doing initial deal triage on inbound leads or MLS/off-market finds.
A8: • Wholesalers, for whom this IS the whole analysis — no lender, no contractor, no itemized budget, ever.
A10: HOW THIS FITS THE TEMPLATE FAMILY
A12: Quick Screen → Borrower / JV Partner (± Seller Financing) → Final client-facing deal analysis. A deal that clears the Quick Screen graduates to a full model once a term sheet and itemized rehab bid exist. Sourced figures (ARV, comps, tax) should carry forward into the fuller model rather than being re-pulled from scratch — see the Source Log tab.
A14: STEP 1 — Assumptions tab
A15: Enter the asking/contract price and ARV. Every sourced figure has a Source, Report/Reference, and Date Pulled column — cite the actual SendFuse Property Profile, Dealio.pro Comps Report, or county assessor record it came from. Trust hierarchy (highest to lowest): County Assessor (verified) > MLS listing data > Dealio.pro Comps/skip-trace > SendFuse Property Profile.
A17: STEP 2 — Rehab Estimate tab
A18: Category-level only — six buckets, not a 50-line contractor bid. Use the optional $/sqft calculator as a sanity check. The Rehab Estimate Stage flag at the top of that tab should always read 'Category-Level Estimate' on this template; a deal that graduates to the Borrower/JV model gets re-flagged 'Itemized (Contractor Confirmed)' there once a real bid exists.
... A30: This stage is lender-agnostic by design — no financing tab exists yet to name one. Once a deal graduates, the Borrower/JV model's Lender field takes whichever of your lender relationships actually issues the term sheet; nothing here should assume a specific lender.

Sheet Deal Screen
A1: Quick Screen (Pre-Diligence) — Deal Read
A2: 4134 E 142nd St, Cleveland, OH 44128 | Quick Screen (Pre-Diligence Stage)
A4: Prepared: | B4: =TODAY() -> 46256 | C4: Stage: | D4: ='Rehab Estimate'!B4 -> Category-Level Estimate (Pre-Diligence)
A5: Prepared For: | B5: [Client / Wholesaler Name] | C5: e.g. "Prepared for Jane Smith at her request" if this is a wholesaler-commissioned marketing copy
A6: PROPERTY & DEAL OVERVIEW
A8: Property Address | B8: =Assumptions!B6 -> 0
A9: Asking / Contract Price | B9: =Assumptions!B8 -> 0 | C9: ARV Source | D9: =Assumptions!C9 -> 0
A10: ARV Estimate | B10: =Assumptions!B9 -> 0 | C10: Tax Source | D10: =Assumptions!C16 -> 0
A11: Rehab Estimate (category-level) | B11: ='Rehab Estimate'!C24 -> 0
A13: QUICK SCREEN RESULTS
A15: 70% Rule Max Allowable Offer (MAO) | B15: ='Screen Results'!B8 -> 0
A16: Spread vs. Asking / Contract Price | B16: ='Screen Results'!B10 -> 0
A17: Wholesale Assignment Fee Potential | B17: ='Screen Results'!B22 -> 0
A18: As-Is Market Position (asking vs. current-condition comps) | B18: ='Screen Results'!B36 -> WITHIN RANGE — asking falls between the average- and median-based as-is estimates
A19: Quick Gross Profit Estimate | B19: ='Screen Results'!B18 -> 0
A20: Quick Margin (% of ARV) | B20: ='Screen Results'!B19 -> 0
A21: Rehab-Risk Flag (deferred maintenance) | B21: ='Rehab Estimate'!B42 -> UNKNOWN — no documented update found; treat major systems as original/end-of-life until proven otherwise
A22: VERDICT
A24: ='Screen Results'!B27 -> PURSUE — proceed to full Borrower/JV model
A25: ='Screen Results'!B28 -> Quick profit $0 (0.0% of ARV) vs. thresholds of $0 / 0.0%. Spread vs. asking: $0.
A28: NOTES
A29: • TEMPLATE — replace all example figures with the actual deal and cite every sourced figure on the Assumptions tab.
A30: • Pre-diligence screen only — no loan terms, no itemized rehab, no waterfall. Not a commitment to lend, an appraisal, or a guarantee of return.
A31: • A deal that clears this screen should graduate to the Borrower or JV Partner template once a term sheet and itemized rehab bid exist.

Sheet Assumptions
A1: Assumptions & Inputs — Quick Screen
A2: Blue/yellow = enter actual figures. Every sourced field cites Source / Report / Date Pulled.
A4: ACQUISITION
B5: Value | C5: Source | D5: Date Pulled | E5: Report / Reference
A6: Property Address | C6: MLS / Client
A7: County / Jurisdiction
A8: Asking / Contract Price | C8: MLS #442988814 (active listing, Pete Cymbal / TimberVine Group), pulled via Dealio.pro
A9: ARV Estimate | D9: =TODAY() -> 46256
A10: Comps Used (count) | C10: Full comp set pulled; all 11 "Flipped"-tagged comps individually verified via transaction-pair method (complete)
A12: PROPERTY DATA (SOURCED — see Source Log tab)
B13: Value | C13: Source | D13: Date Pulled | E13: Report / Reference
A14: As-Is Value (assessor/appraisal) | D14: =TODAY() -> 46256
A15: Beds / Baths / Sq Ft | C15: Cross-check SendFuse vs. Assessor — SendFuse known to mislabel prior-owner data
A16: Annual Property Tax | D16: =TODAY() -> 46256
A17: Current Owner / Debt Stack Notes | D17: =TODAY() -> 46256
A19: Trust hierarchy (highest to lowest):
A20: County Assessor (verified) > MLS listing data > Dealio.pro Comps/skip-trace > SendFuse Property Profile.
A22: REHAB ESTIMATE
A24: Total Rehab Estimate (category-level — see Rehab Estimate tab) | B24: ='Rehab Estimate'!C24 -> 0
A25: Rehab Estimate Stage | B25: ='Rehab Estimate'!B4 -> Category-Level Estimate (Pre-Diligence)
A27: HOLDING COST ESTIMATE (rough — not a lender reserve)
A29: Property Tax (monthly, from annual above) | B29: =B16/12 -> 0
A30: Insurance (monthly, est.) | C30: PLACEHOLDER — not sourced
A31: Utilities (monthly, est. — vacant/rehab) | C31: PLACEHOLDER — not sourced
A32: HOA Dues (monthly) | C32: PLACEHOLDER — not sourced
A34: PROJECTED TIMELINE
A36: Estimated Hold Period (months, rough) | C36: Rehab + marketing/closing, ballpark for this stage
A38: PROJECTED DISPOSITION
A40: Target Sale Price | B40: =B9 -> 0
A41: Selling Commission (% of sale price)
A42: Selling Closing Costs (% of sale price)
A44: SCREEN THRESHOLDS (verdict cutoffs — adjust per buyer/deal)
A46: Minimum Acceptable Profit ($)
A47: Minimum Acceptable Margin (% of ARV)
A49: AS-IS MARKET CHECK (Rule 5 — is the asking price fair for current condition, before rehab?)
A50: Pull non-flipped comps from the same comp set already gathered for ARV (no separate pull) — no "Flipped" tag, no confirmed transaction-pair renovation. This checks whether you're paying above or below as-is market, independent of the ARV question.
A53: Subject Square Footage | C53: From Beds/Baths/Sqft field above — kept numeric here for calculation
B54: Value | C54: Source
A55: As-Is Comp $/Sqft — Average
A56: As-Is Comp $/Sqft — Median
...

Sheet Rehab Estimate
A1: Rehab Estimate — Category-Level
A2: Six buckets, NOT an itemized contractor bid — replace category totals as diligence progresses
A4: REHAB ESTIMATE STAGE: | B4: Category-Level Estimate (Pre-Diligence)
A5: This flag should read "Itemized (Contractor Confirmed)" only once a real contractor bid replaces these category totals — that happens on the Borrower/JV Partner template, not here.
A7: CATEGORY-LEVEL ESTIMATE (enter directly, or use the calculator below as a sanity check)
A9: Category | B9: Estimated Cost | C9: Basis / Notes
A10: Exterior | C10: PLACEHOLDER — visual/drive-by estimate, not a bid
A11: Interior / Structural | C11: PLACEHOLDER — visual/drive-by estimate, not a bid
A12: Kitchen | C12: PLACEHOLDER — visual/drive-by estimate, not a bid
A13: Bathroom(s) | C13: PLACEHOLDER — visual/drive-by estimate, not a bid
A14: Systems (Elec / HVAC / Plumbing) | C14: PLACEHOLDER — visual/drive-by estimate, not a bid
A15: Admin / Contingency (~10%) | C15: PLACEHOLDER — visual/drive-by estimate, not a bid
A19: OPTIONAL — $/SQFT SANITY-CHECK CALCULATOR
A21: Square Footage
A22: Rehab Tier (Light $15-25/sf, Medium $25-40/sf, Heavy $40-65/sf)
A23: Assumed $/Sqft for Tier | C23: =B21*B23 -> 0 | D23: <- suggested total; compare against category sum above
A24: TOTAL REHAB ESTIMATE (feeds Assumptions & Deal Screen) | C24: =SUM(B10:B15) -> 0
A27: DEFERRED MAINTENANCE / COMPONENT AGE SIGNAL
A28: Separate from ARV — this estimates how much of the property's major-system lifespan is used up, as a rehab-risk check. A confirmed transaction-pair renovation (real purchase-then-resale price jump) is the strongest source; an assessed-value jump or MLS listing history are weaker but usable. Sale recency alone is NOT evidence of a recent update — a property can change owners without any work being done.
A31: Last Documented Update — Year
A32: Signal Source
A33: Options: Confirmed renovation (transaction-pair) / Assessed-value jump / MLS listing history / None found — treat as original
A34: Years Since Last Documented Update | B34: =IF(ISNUMBER(B31),YEAR(TODAY())-B31,"n/a") -> n/a
A36: TYPICAL COMPONENT LIFESPANS (reference — not deal-specific)
A38: Roof | B38: 20-25 yrs
A39: HVAC | B39: 15-20 yrs
A40: Plumbing / Electrical | B40: Often original in pre-1960s stock unless documented otherwise
A42: Rehab-Risk Flag | B42: =IF(NOT(ISNUMBER(B31)),"UNKNOWN — no documented update found; treat major systems as original/end-of-life until proven otherwise",IF(B34>=25,"HIGH — years since update exceeds typical roof lifespan; assume major systems at/past end of life",IF(B34>=15,"MODERATE — likely at or near HVAC end of life; verify roof/systems condition","LOWER — within typical component lifespans, but confirm during walkthrough"))) -> UNKNOWN — no documented update found; treat major systems as original/end-of-life until proven otherwise

Sheet Source Log
A1: Source Log — Citations
A2: Every pulled report, logged so any figure in this workbook traces back to a named, dated source
A4: SOURCE LOG
A6: Source | B6: Report Type | C6: Field(s) Sourced | D6: Date Pulled | E6: File / Reference | F6: Notes
D7: =TODAY() -> 46256 | E7: [Parcel # / record link]
D8: =TODAY() -> 46256 | E8: [lpp-export- filename or report PDF name]
D9: =TODAY() -> 46256 | E9: [lpp-export- CSV filename]
D10: =TODAY() -> 46256 | E10: [SendFuse report name / order #]
D11: =TODAY() -> 46256
A13: Trust hierarchy (highest to lowest): County Assessor (verified) > MLS listing data > Dealio.pro Comps/skip-trace > SendFuse Property Profile. Flag conflicts between sources rather than silently picking one.
A16: Keep the actual exported PDFs/CSVs alongside this workbook — this log is the index, not a substitute for the source documents themselves.

Sheet Screen Results
A1: Screen Results — 70% Rule, Spread & Verdict
A2: All formulas — nothing entered directly on this tab
A4: 70% RULE — MAXIMUM ALLOWABLE OFFER
A6: ARV Estimate | B6: =Assumptions!B9 -> 0
A7: Less: Rehab Estimate | B7: =-'Rehab Estimate'!C24 -> 0
A8: MAO (70% x ARV − Rehab Estimate) | B8: =Assumptions!B9*0.7+B7 -> 0
A9: Asking / Contract Price | B9: =Assumptions!B8 -> 0
A10: Spread (MAO − Asking/Contract Price) | B10: =B8-B9 -> 0
A11: Positive = room under the 70% ceiling. Negative = asking price exceeds the MAO at this rehab estimate.
A13: QUICK GROSS PROFIT ESTIMATE (no financing costs — pre-term-sheet)
A15: Target Sale Price (= ARV) | B15: =Assumptions!B40 -> 0
A16: Less: Selling Commission + Closing Costs | B16: =-Assumptions!B40*(Assumptions!B41+Assumptions!B42) -> 0
A17: Less: Purchase Price, Rehab Estimate & Holding Cost Estimate | B17: =-(Assumptions!B8+'Rehab Estimate'!C24+(Assumptions!B29+Assumptions!B30+Assumptions!B31+Assumptions!B32)*Assumptions!B36) -> 0
A18: QUICK GROSS PROFIT ESTIMATE | B18: =B15+B16+B17 -> 0
A19: Quick Margin (% of ARV) | B19: =IFERROR(B18/Assumptions!B9,0) -> 0
A21: WHOLESALE VIEW
A22: Assignment Fee Potential (MAO − Contract Price) | B22: =B10 -> 0
A23: Same figure as Spread above — framed as room to assign to a cash buyer at or under the 70% ceiling.
A25: VERDICT
A27: Verdict | B27: =IF(AND(B18>=Assumptions!B46,B19>=Assumptions!B47),"PURSUE — proceed to full Borrower/JV model",IF(B18>0,"MARGINAL — clears $0 but below your thresholds; further diligence optional","PASS — does not clear a profitable spread at these estimates")) -> PURSUE — proceed to full Borrower/JV model
B28: ="Quick profit "&TEXT(B18,"$#,##0")&" ("&TEXT(B19,"0.0%")&" of ARV) vs. thresholds of "&TEXT(Assumptions!B46,"$#,##0")&" / "&TEXT(Assumptions!B47,"0.0%")&". Spread vs. asking: "&TEXT(B10,"$#,##0")&"." -> Quick profit $0 (0.0% of ARV) vs. thresholds of $0 / 0.0%. Spread vs. asking: $0.
A31: AS-IS MARKET CHECK (Rule 5 — asking price vs. current-condition comps)
A33: As-Is Comp Range — Average-based | B33: =Assumptions!B53*Assumptions!B55 -> 0
A34: As-Is Comp Range — Median-based | B34: =Assumptions!B53*Assumptions!B56 -> 0
A35: Asking / Contract Price | B35: =B9 -> 0
A36: As-Is Market Position | B36: =IF(B35<MIN(B33,B34),"UNDER MARKET — asking is below both as-is comp estimates",IF(B35>MAX(B33,B34),"OVER MARKET — asking exceeds both as-is comp estimates","WITHIN RANGE — asking falls between the average- and median-based as-is estimates")) -> WITHIN RANGE — asking falls between the average- and median-based as-is estimates
